<?xml version="1.0" ?>
<!-- =================================================================================== -->
<!-- |    This document was autogenerated by xacro from butler51.urdf.xacro            | -->
<!-- |    EDITING THIS FILE BY HAND IS NOT RECOMMENDED                                 | -->
<!-- =================================================================================== -->
<robot name="butler5" xmlns:xacro="http://www.ros.org/wiki/xacro">
  <material name="Black">
    <color rgba="0.0 0.0 0.0 1.0"/>
  </material>
  <material name="Blue">
    <color rgba="0.0 0.0 0.8 1.0"/>
  </material>
  <material name="Green">
    <color rgba="0.0 0.1 0.0 1.0"/>
  </material>
  <material name="DarkGreen">
    <color rgba="0.2 0.6 0.0 1.0"/>
  </material>
  <material name="Gray">
    <color rgba="0.7 0.7 0.7 1.0"/>
  </material>
  <material name="DarkGray">
    <color rgba="0.3 0.3 0.3 1.0"/>
  </material>
  <material name="Red">
    <color rgba="0.8 0.0 0.0 1.0"/>
  </material>
  <material name="Purple">
    <color rgba="1.0 0.0 1.0 1.0"/>
  </material>
  <material name="White">
    <color rgba="1.0 1.0 1.0 1.0"/>
  </material>
  <material name="Yellow">
    <color rgba="0.8 0.8 0.0 1.0"/>
  </material>
  <!-- in kg-->
  <!--
  <property name="base_x_origin_to_wheel_origin" value="0.25" />
  <property name="base_y_origin_to_wheel_origin" value="0.3" />
  <property name="base_z_origin_to_wheel_origin" value="0.0" />
-->
  <!-- in kg-->
  <!--
  <property name="base_x_origin_to_wheel_origin" value="0.25" />
  <property name="base_y_origin_to_wheel_origin" value="0.3" />
  <property name="base_z_origin_to_wheel_origin" value="0.0" />
-->
  <link name="base_link">
    <inertial>
      <origin rpy="1.57079632679 0 0" xyz="0.17 0.0022486 -0.08"/>
      <mass value="15"/>
      <inertia ixx="0.0044425" ixy="0" ixz="0" iyy="0.00714125" iyz="0" izz="0.00714125"/>
    </inertial>
    <visual>
      <origin rpy="1.57079632679 0 0" xyz="0.17 0.0022486 -0.08"/>
      <geometry>
        <mesh filename="package://butler5/meshes/base_link.STL"/>
      </geometry>
      <material name="">
        <color rgba="1 1 1 1"/>
      </material>
    </visual>
    <collision>
      <origin rpy="1.57079632679 0 0" xyz="0.17 0.0022486 -0.08"/>
      <geometry>
        <mesh filename="package://butler5/meshes/base_link.STL"/>
        <!--<box size="0.65 0.50 0.20"/>-->
      </geometry>
    </collision>
  </link>
  <gazebo reference="base_link">
    <material>Gazebo/Green</material>
    <turnGravityOff>false</turnGravityOff>
  </gazebo>
  <link name="tower">
    <inertial>
      <origin rpy="0 0 0" xyz="-0.0034061 -1.2124E-10 -0.048553"/>
      <mass value="0.0031399"/>
      <inertia ixx="0.0013028" ixy="0" ixz="-1.26E-06" iyy="0.001174" iyz="0" izz="0.0020233"/>
    </inertial>
    <visual>
      <origin rpy="0 0 0" xyz="0 0 -0.08"/>
      <geometry>
        <mesh filename="package://butler5/meshes/tower.STL"/>
      </geometry>
      <material name="">
        <color rgba="0.75294 0.75294 0.75294 1"/>
      </material>
    </visual>
    <!-- <collision>
      <origin xyz="0 0 0" rpy="0 0 0" />
      <geometry>
        <mesh filename="package://butler5/meshes/tower.STL" />
      </geometry>
    </collision>-->
  </link>
  <gazebo reference="tower">
    <turnGravityOff>false</turnGravityOff>
  </gazebo>
  <joint name="tower_joint" type="revolute">
    <origin rpy="0 0 0" xyz="0.34 0 0.55878"/>
    <parent link="base_link"/>
    <child link="tower"/>
    <axis xyz="0 0 1"/>
    <limit effort="0.5" lower="-1.57079632679" upper="1.57079632679" velocity="0.78539816339"/>
  </joint>
  <!-- <link name="kinect">
    <inertial>
      <origin xyz="0.12303 3.7194E-08 -0.00089767" rpy="0 0 0" />
     <mass
        value="0.00035067" />
      <inertia
        ixx="0.00038172"
        ixy="0"
        ixz="-6.57E-06"
        iyy="0.0028934"
        iyz="-2E-08"
        izz="0.0031072" />
    </inertial>
    <visual>
        <geometry>
       <box size="0.064 0.121 0.0381"/>
    </geometry>
     <material name="Blue"/>
     <origin xyz="0 0 0"/>
     </visual>
  </link>

  <joint name="kinect_joint" type="fixed">
     <origin xyz="-0.2 0 0.2" rpy="0 ${M_PI/10} 0"/>
     <<origin xyz="0.5 0 0.84" rpy="0 ${M_PI/10} 0"/>
     <parent link="tower"/>
     <child link="kinect"/>
  </joint>-->
  <link name="arm_base">
    <inertial>
      <origin rpy="0 0 0" xyz="-0.0040016 4.112E-08 -0.00090622"/>
      <mass value="0.0031399"/>
      <inertia ixx="0.00018906" ixy="0" ixz="0" iyy="0.005442" iyz="0" izz="0.0055646"/>
    </inertial>
    <visual>
      <origin rpy="0 0 0" xyz="-0.0040016 4.112E-08 -0.00090622"/>
      <geometry>
        <mesh filename="package://butler5/meshes/arm_base.STL"/>
      </geometry>
      <material name="">
        <color rgba="0.75294 0.75294 0.75294 1"/>
      </material>
    </visual>
    <!-- <collision>
      <origin xyz="0 0 0" rpy="0 0 0" />
      <geometry>
        <mesh filename="package://butler5/meshes/arm_base.STL" />
      </geometry>
    </collision>-->
  </link>
  <gazebo reference="arm_base">
    <turnGravityOff>false</turnGravityOff>
  </gazebo>
  <joint name="arm_base_joint" type="prismatic">
    <origin rpy="0 0 0" xyz="0 0 0.0081114"/>
    <parent link="tower"/>
    <child link="arm_base"/>
    <axis xyz="0 0 1"/>
    <limit effort="10" lower="-0.32" upper="0.32" velocity="0.1"/>
  </joint>
  <link name="arm_first">
    <inertial>
      <origin rpy="0 0 0" xyz="0.14167 5.1317E-07 6.6613E-16"/>
      <!--<mass value="0.33757" />-->
      <mass value="0.0033757"/>
      <inertia ixx="0.00018906" ixy="0" ixz="0" iyy="0.005442" iyz="0" izz="0.0055646"/>
    </inertial>
    <visual>
      <origin rpy="0 0 0" xyz="0 0 0"/>
      <geometry>
        <mesh filename="package://butler5/meshes/arm_first.STL"/>
      </geometry>
      <material name="">
        <color rgba="0.75294 0.75294 0.75294 1"/>
      </material>
    </visual>
    <!--<collision>
      <origin xyz="0 0 0" rpy="0 0 0" />
      <geometry>
        <mesh filename="package://butler5/meshes/arm_first.STL" />
      </geometry>
    </collision>-->
  </link>
  <gazebo reference="arm_first">
    <turnGravityOff>false</turnGravityOff>
  </gazebo>
  <joint name="arm_first_joint" type="revolute">
    <origin rpy="0 0 0" xyz="0.0501 0 0"/>
    <parent link="arm_base"/>
    <child link="arm_first"/>
    <axis xyz="0 1 0"/>
    <limit effort="5" lower="-1.5708" upper="1.5708" velocity="0.7854"/>
  </joint>
  <link name="arm_second">
    <inertial>
      <origin rpy="0 0 0" xyz="0.12303 3.7194E-08 -0.00089767"/>
      <mass value="0.0035067"/>
      <inertia ixx="0.00038172" ixy="0" ixz="-6.57E-06" iyy="0.0028934" iyz="-2E-08" izz="0.0031072"/>
    </inertial>
    <visual>
      <origin rpy="0 0 0" xyz="0 0 0"/>
      <geometry>
        <mesh filename="package://butler5/meshes/arm_second.STL"/>
      </geometry>
      <material name="">
        <color rgba="0.75294 0.75294 0.75294 1"/>
      </material>
    </visual>
    <collision>
      <origin rpy="0 0 0" xyz="0 0 0"/>
      <geometry>
        <mesh filename="package://butler5/meshes/arm_second.STL"/>
      </geometry>
    </collision>
  </link>
  <gazebo reference="arm_second">
    <turnGravityOff>false</turnGravityOff>
  </gazebo>
  <joint name="arm_second_joint" type="revolute">
    <origin rpy="0 0 0" xyz="0.3 0 0"/>
    <parent link="arm_first"/>
    <child link="arm_second"/>
    <axis xyz="0 1 0"/>
    <limit effort="3" lower="-1.57079632679" upper="1.57079632679" velocity="0.78539816339"/>
  </joint>
  <link name="hand">
    <inertial>
      <origin rpy="0 0 0" xyz="0.1 0 0"/>
      <mass value="0.0035067"/>
      <inertia ixx="0.00038172" ixy="0" ixz="-6.57E-06" iyy="0.0028934" iyz="-2E-08" izz="0.0031072"/>
    </inertial>
    <visual>
      <origin rpy="0 0 0" xyz="0.1 0 0"/>
      <geometry>
        <box size="0.1 0.1 0.1"/>
      </geometry>
      <material name="">
        <color rgba="0.75294 0.75294 0.75294 1"/>
      </material>
    </visual>
    <collision>
      <origin rpy="0 0 0" xyz="0.1 0 0"/>
      <geometry>
        <box size="0.1 0.1 0.1"/>
      </geometry>
    </collision>
  </link>
  <!--
<joint name="hand_joint" type="revolute">
    <origin xyz="0.175 0 0" rpy="0 0 0" />
    <parent link="arm_second" />
    <child link="hand" />
    <axis xyz="1 0 0" />
    <limit
      lower="-1.57079632679"
      upper="1.57079632679"
      effort="3"
      velocity="0.78539816339" />
  </joint>
-->
  <joint name="hand_joint" type="fixed">
    <origin rpy="0 0 0" xyz="0.175 0 0"/>
    <parent link="arm_second"/>
    <child link="hand"/>
  </joint>
  <gazebo reference="hand">
    <turnGravityOff>false</turnGravityOff>
  </gazebo>
  <transmission name="tower_joint_trans">
    <type>transmission_interface/SimpleTransmission</type>
    <actuator name="$tower_joint_motor">
      <mechanicalReduction>1</mechanicalReduction>
    </actuator>
    <joint name="tower_joint">
      <hardwareInterface>PositionJointInterface</hardwareInterface>
    </joint>
  </transmission>
  <transmission name="arm_base_joint_trans">
    <type>transmission_interface/SimpleTransmission</type>
    <actuator name="$arm_base_joint_motor">
      <mechanicalReduction>1</mechanicalReduction>
    </actuator>
    <joint name="arm_base_joint">
      <hardwareInterface>PositionJointInterface</hardwareInterface>
    </joint>
  </transmission>
  <transmission name="arm_first_joint_trans">
    <type>transmission_interface/SimpleTransmission</type>
    <actuator name="$arm_first_joint_motor">
      <mechanicalReduction>1</mechanicalReduction>
    </actuator>
    <joint name="arm_first_joint">
      <hardwareInterface>PositionJointInterface</hardwareInterface>
    </joint>
  </transmission>
  <transmission name="arm_second_joint_trans">
    <type>transmission_interface/SimpleTransmission</type>
    <actuator name="$arm_second_joint_motor">
      <mechanicalReduction>1</mechanicalReduction>
    </actuator>
    <joint name="arm_second_joint">
      <hardwareInterface>PositionJointInterface</hardwareInterface>
    </joint>
  </transmission>
  <!--fb : front, back ; lr: left, right -->
  <link name="back_right_wheel">
    <visual>
      <origin rpy="1.57079632679 0 0" xyz="0 0 0"/>
      <geometry>
        <cylinder length="0.032" radius="0.1225"/>
      </geometry>
      <material name="Black"/>
    </visual>
    <collision>
      <origin rpy="1.57079632679 0 0" xyz="0 0 0"/>
      <geometry>
        <cylinder length="0.032" radius="0.1225"/>
      </geometry>
    </collision>
    <inertial>
      <mass value="0.5"/>
      <!-- <origin xyz="0 0 0" rpy="${flip*M_PI/2} 0 0"/> -->
      <origin xyz="0 0 0"/>
      <inertia ixx="0.00191844791667" ixy="0" ixz="0" iyy="0.00191844791667" iyz="0" izz="0.0037515625"/>
    </inertial>
  </link>
  <gazebo reference="back_right_wheel">
    <mu1 value="100.0"/>
    <mu2 value="100.0"/>
    <kp value="10000000.0"/>
    <kd value="1.0"/>
    <fdir1 value="1 0 0"/>
    <material>Gazebo/Black</material>
    <turnGravityOff>false</turnGravityOff>
  </gazebo>
  <joint name="back_right_wheel_joint" type="continuous">
    <parent link="base_link"/>
    <child link="back_right_wheel"/>
    <origin rpy="0 0 0" xyz="0.0 -0.24 0.0"/>
    <axis rpy="0 0 0" xyz="0 1 0"/>
    <limit effort="1000" velocity="100"/>
    <joint_properties damping="0.0" friction="0.0"/>
  </joint>
  <!-- Transmission is important to link the joints and the controller -->
  <!--
    <transmission name="${fb}_${lr}_wheel_joint_trans">
      <type>transmission_interface/SimpleTransmission</type>
      <joint name="${fb}_${lr}_wheel_joint">
        <hardwareInterface>EffortJointInterface</hardwareInterface>
      </joint>
      <actuator name="${fb}_${lr}_wheel_joint_motor">
        <hardwareInterface>EffortJointInterface</hardwareInterface>
        <mechanicalReduction>1</mechanicalReduction>
      </actuator>
    </transmission>-->
  <!--fb : front, back ; lr: left, right -->
  <link name="back_left_wheel">
    <visual>
      <origin rpy="1.57079632679 0 0" xyz="0 0 0"/>
      <geometry>
        <cylinder length="0.032" radius="0.1225"/>
      </geometry>
      <material name="Black"/>
    </visual>
    <collision>
      <origin rpy="1.57079632679 0 0" xyz="0 0 0"/>
      <geometry>
        <cylinder length="0.032" radius="0.1225"/>
      </geometry>
    </collision>
    <inertial>
      <mass value="0.5"/>
      <!-- <origin xyz="0 0 0" rpy="${flip*M_PI/2} 0 0"/> -->
      <origin xyz="0 0 0"/>
      <inertia ixx="0.00191844791667" ixy="0" ixz="0" iyy="0.00191844791667" iyz="0" izz="0.0037515625"/>
    </inertial>
  </link>
  <gazebo reference="back_left_wheel">
    <mu1 value="100.0"/>
    <mu2 value="100.0"/>
    <kp value="10000000.0"/>
    <kd value="1.0"/>
    <fdir1 value="1 0 0"/>
    <material>Gazebo/Black</material>
    <turnGravityOff>false</turnGravityOff>
  </gazebo>
  <joint name="back_left_wheel_joint" type="continuous">
    <parent link="base_link"/>
    <child link="back_left_wheel"/>
    <origin rpy="0 0 0" xyz="0.0 0.24 0.0"/>
    <axis rpy="0 0 0" xyz="0 1 0"/>
    <limit effort="1000" velocity="100"/>
    <joint_properties damping="0.0" friction="0.0"/>
  </joint>
  <!-- Transmission is important to link the joints and the controller -->
  <!--
    <transmission name="${fb}_${lr}_wheel_joint_trans">
      <type>transmission_interface/SimpleTransmission</type>
      <joint name="${fb}_${lr}_wheel_joint">
        <hardwareInterface>EffortJointInterface</hardwareInterface>
      </joint>
      <actuator name="${fb}_${lr}_wheel_joint_motor">
        <hardwareInterface>EffortJointInterface</hardwareInterface>
        <mechanicalReduction>1</mechanicalReduction>
      </actuator>
    </transmission>-->
  <!--fb : front, back ; lr: left, right -->
  <link name="sw_arm_right_1">
    <inertial>
      <mass value="0.01"/>
      <origin xyz="0 0 0"/>
      <inertia ixx="3.04e-06" ixy="0" ixz="0" iyy="3.04e-06" iyz="0" izz="8e-08"/>
    </inertial>
    <visual>
      <geometry>
        <cylinder length="0.06" radius="0.004"/>
      </geometry>
      <material name="silver">
        <color rgba="0.3 0.3 0.3 1"/>
      </material>
      <origin rpy="0 0 0" xyz="0 0 -0.03"/>
    </visual>
  </link>
  <joint name="sw_arm_right_connect_1" type="continuous">
    <origin rpy="0 0 0" xyz="0.355 -0.16 0.03"/>
    <axis rpy="0 0 0" xyz="0 0 1"/>
    <parent link="base_link"/>
    <child link="sw_arm_right_1"/>
    <limit effort="100" velocity="100"/>
    <joint_properties damping="0.0" friction="0.0"/>
  </joint>
  <link name="sw_arm_right_2">
    <inertial>
      <mass value="0.01"/>
      <origin xyz="0 0 0"/>
      <inertia ixx="1.37333333333e-06" ixy="0" ixz="0" iyy="1.37333333333e-06" iyz="0" izz="8e-08"/>
    </inertial>
    <visual>
      <geometry>
        <cylinder length="0.04" radius="0.004"/>
      </geometry>
      <material name="silver">
        <color rgba="0.3 0.3 0.3 1"/>
      </material>
      <origin rpy="0 0 0" xyz="0 0 0.02"/>
    </visual>
  </link>
  <joint name="sw_arm_right_connect_2" type="fixed">
    <origin rpy="1.5707 0 0" xyz="0 0 -0.06"/>
    <parent link="sw_arm_right_1"/>
    <child link="sw_arm_right_2"/>
  </joint>
  <link name="sw_arm_right_3">
    <inertial>
      <mass value="0.01"/>
      <origin xyz="0 0 0"/>
      <inertia ixx="3.04e-06" ixy="0" ixz="0" iyy="3.04e-06" iyz="0" izz="8e-08"/>
    </inertial>
    <visual>
      <geometry>
        <cylinder length="0.06" radius="0.004"/>
      </geometry>
      <material name="silver">
        <color rgba="0.3 0.3 0.3 1"/>
      </material>
      <origin rpy="0 0 0" xyz="0 0 -0.03"/>
    </visual>
  </link>
  <joint name="sw_arm_right_connect_3" type="fixed">
    <origin rpy="-1.5707 0 -0.78" xyz="0 0 0.04"/>
    <parent link="sw_arm_right_2"/>
    <child link="sw_arm_right_3"/>
  </joint>
  <link name="sw_arm_right_4">
    <inertial>
      <mass value="0.01"/>
      <origin xyz="0 0 0"/>
      <inertia ixx="1.37333333333e-06" ixy="0" ixz="0" iyy="1.37333333333e-06" iyz="0" izz="8e-08"/>
    </inertial>
    <visual>
      <geometry>
        <cylinder length="0.04" radius="0.004"/>
      </geometry>
      <material name="silver">
        <color rgba="0.3 0.3 0.3 1"/>
      </material>
      <origin rpy="0 0 0" xyz="0 0 -0.02"/>
    </visual>
  </link>
  <joint name="sw_arm_right_connect_4" type="fixed">
    <origin rpy="1.5707 0 0" xyz="0 0 -0.060"/>
    <parent link="sw_arm_right_3"/>
    <child link="sw_arm_right_4"/>
  </joint>
  <!-- Wheel connected to fourth-->
  <link name="front_right_swivel_wheel">
    <visual>
      <origin rpy="0.0 0 0" xyz="0 0 0"/>
      <geometry>
        <cylinder length="0.05" radius="0.05"/>
      </geometry>
      <material name="Black"/>
    </visual>
    <collision>
      <origin rpy="0 0 0" xyz="0 0 0"/>
      <geometry>
        <cylinder length="0.05" radius="0.05"/>
      </geometry>
    </collision>
    <inertial>
      <mass value="0.5"/>
      <origin xyz="0 0 0"/>
      <inertia ixx="0.000416666666667" ixy="0" ixz="0" iyy="0.000416666666667" iyz="0" izz="0.000625"/>
    </inertial>
  </link>
  <gazebo reference="front_right_swivel_wheel">
    <mu1 value="0.8"/>
    <mu2 value="0.8"/>
    <kp value="10000000.0"/>
    <kd value="1.0"/>
    <fdir1 value="1 0 0"/>
    <material>Gazebo/Black</material>
    <turnGravityOff>false</turnGravityOff>
  </gazebo>
  <joint name="front_right_swivel_wheel_joint" type="continuous">
    <parent link="sw_arm_right_4"/>
    <child link="front_right_swivel_wheel"/>
    <origin rpy="0 0 0" xyz="0 0 -0.04"/>
    <axis rpy="0 0 0" xyz="0 0 1"/>
    <limit effort="100" velocity="100"/>
    <joint_properties damping="0.0" friction="0.0"/>
  </joint>
  <!-- Transmission is important to link the joints and the controller -->
  <transmission name="front_right_swivel_wheel_joint_trans">
    <type>transmission_interface/SimpleTransmission</type>
    <joint name="front_right_swivel_wheel_joint">
      <hardwareInterface>EffortJointInterface</hardwareInterface>
    </joint>
    <actuator name="front_right_swivel_wheel_joint_motor">
      <hardwareInterface>EffortJointInterface</hardwareInterface>
      <mechanicalReduction>1</mechanicalReduction>
    </actuator>
  </transmission>
  <!--fb : front, back ; lr: left, right -->
  <link name="sw_arm_left_1">
    <inertial>
      <mass value="0.01"/>
      <origin xyz="0 0 0"/>
      <inertia ixx="3.04e-06" ixy="0" ixz="0" iyy="3.04e-06" iyz="0" izz="8e-08"/>
    </inertial>
    <visual>
      <geometry>
        <cylinder length="0.06" radius="0.004"/>
      </geometry>
      <material name="silver">
        <color rgba="0.3 0.3 0.3 1"/>
      </material>
      <origin rpy="0 0 0" xyz="0 0 -0.03"/>
    </visual>
  </link>
  <joint name="sw_arm_left_connect_1" type="continuous">
    <origin rpy="0 0 0" xyz="0.355 0.16 0.03"/>
    <axis rpy="0 0 0" xyz="0 0 1"/>
    <parent link="base_link"/>
    <child link="sw_arm_left_1"/>
    <limit effort="100" velocity="100"/>
    <joint_properties damping="0.0" friction="0.0"/>
  </joint>
  <link name="sw_arm_left_2">
    <inertial>
      <mass value="0.01"/>
      <origin xyz="0 0 0"/>
      <inertia ixx="1.37333333333e-06" ixy="0" ixz="0" iyy="1.37333333333e-06" iyz="0" izz="8e-08"/>
    </inertial>
    <visual>
      <geometry>
        <cylinder length="0.04" radius="0.004"/>
      </geometry>
      <material name="silver">
        <color rgba="0.3 0.3 0.3 1"/>
      </material>
      <origin rpy="0 0 0" xyz="0 0 0.02"/>
    </visual>
  </link>
  <joint name="sw_arm_left_connect_2" type="fixed">
    <origin rpy="1.5707 0 0" xyz="0 0 -0.06"/>
    <parent link="sw_arm_left_1"/>
    <child link="sw_arm_left_2"/>
  </joint>
  <link name="sw_arm_left_3">
    <inertial>
      <mass value="0.01"/>
      <origin xyz="0 0 0"/>
      <inertia ixx="3.04e-06" ixy="0" ixz="0" iyy="3.04e-06" iyz="0" izz="8e-08"/>
    </inertial>
    <visual>
      <geometry>
        <cylinder length="0.06" radius="0.004"/>
      </geometry>
      <material name="silver">
        <color rgba="0.3 0.3 0.3 1"/>
      </material>
      <origin rpy="0 0 0" xyz="0 0 -0.03"/>
    </visual>
  </link>
  <joint name="sw_arm_left_connect_3" type="fixed">
    <origin rpy="-1.5707 0 -0.78" xyz="0 0 0.04"/>
    <parent link="sw_arm_left_2"/>
    <child link="sw_arm_left_3"/>
  </joint>
  <link name="sw_arm_left_4">
    <inertial>
      <mass value="0.01"/>
      <origin xyz="0 0 0"/>
      <inertia ixx="1.37333333333e-06" ixy="0" ixz="0" iyy="1.37333333333e-06" iyz="0" izz="8e-08"/>
    </inertial>
    <visual>
      <geometry>
        <cylinder length="0.04" radius="0.004"/>
      </geometry>
      <material name="silver">
        <color rgba="0.3 0.3 0.3 1"/>
      </material>
      <origin rpy="0 0 0" xyz="0 0 -0.02"/>
    </visual>
  </link>
  <joint name="sw_arm_left_connect_4" type="fixed">
    <origin rpy="1.5707 0 0" xyz="0 0 -0.060"/>
    <parent link="sw_arm_left_3"/>
    <child link="sw_arm_left_4"/>
  </joint>
  <!-- Wheel connected to fourth-->
  <link name="front_left_swivel_wheel">
    <visual>
      <origin rpy="0.0 0 0" xyz="0 0 0"/>
      <geometry>
        <cylinder length="0.05" radius="0.05"/>
      </geometry>
      <material name="Black"/>
    </visual>
    <collision>
      <origin rpy="0 0 0" xyz="0 0 0"/>
      <geometry>
        <cylinder length="0.05" radius="0.05"/>
      </geometry>
    </collision>
    <inertial>
      <mass value="0.5"/>
      <origin xyz="0 0 0"/>
      <inertia ixx="0.000416666666667" ixy="0" ixz="0" iyy="0.000416666666667" iyz="0" izz="0.000625"/>
    </inertial>
  </link>
  <gazebo reference="front_left_swivel_wheel">
    <mu1 value="0.8"/>
    <mu2 value="0.8"/>
    <kp value="10000000.0"/>
    <kd value="1.0"/>
    <fdir1 value="1 0 0"/>
    <material>Gazebo/Black</material>
    <turnGravityOff>false</turnGravityOff>
  </gazebo>
  <joint name="front_left_swivel_wheel_joint" type="continuous">
    <parent link="sw_arm_left_4"/>
    <child link="front_left_swivel_wheel"/>
    <origin rpy="0 0 0" xyz="0 0 -0.04"/>
    <axis rpy="0 0 0" xyz="0 0 1"/>
    <limit effort="100" velocity="100"/>
    <joint_properties damping="0.0" friction="0.0"/>
  </joint>
  <!-- Transmission is important to link the joints and the controller -->
  <transmission name="front_left_swivel_wheel_joint_trans">
    <type>transmission_interface/SimpleTransmission</type>
    <joint name="front_left_swivel_wheel_joint">
      <hardwareInterface>EffortJointInterface</hardwareInterface>
    </joint>
    <actuator name="front_left_swivel_wheel_joint_motor">
      <hardwareInterface>EffortJointInterface</hardwareInterface>
      <mechanicalReduction>1</mechanicalReduction>
    </actuator>
  </transmission>
  <!-- GAZEBO STUFF -->
  <gazebo>
    <plugin filename="libam_gazebo_controller_2wd.so" name="automower_gazebo_controller">
      <alwaysOn>true</alwaysOn>
      <updateRate>100.0</updateRate>
      <leftJoint>back_right_wheel_joint</leftJoint>
      <rightJoint>back_left_wheel_joint</rightJoint>
      <wheelSeparation>0.4645</wheelSeparation>
      <wheelDiameter>0.245</wheelDiameter>
      <wheelTorque>100</wheelTorque>
      <commandTopic>cmd_vel</commandTopic>
      <odometryTopic>odom</odometryTopic>
      <odometryFrame>odom_gazebo</odometryFrame>
      <robotBaseFrame>base_link</robotBaseFrame>
      <publishWheelTF>false</publishWheelTF>
      <publishWheelJointState>false</publishWheelJointState>
    </plugin>
    <plugin filename="libgazebo_ros_control.so" name="gazebo_ros_control"/>
    <plugin filename="libhector_gazebo_ros_imu.so" name="imu_plugin">
      <alwaysOn>true</alwaysOn>
      <bodyName>base_link</bodyName>
      <topicName>imu</topicName>
      <serviceName>imu_service</serviceName>
      <updateRate>100.0</updateRate>
      <rpyOffsets>0 0 0</rpyOffsets>
      <gaussianNoise>0.0</gaussianNoise>
      <accelDrift>0.0 0.0 0.0</accelDrift>
      <accelGaussianNoise>0.0 0.0 0.0</accelGaussianNoise>
      <rateDrift>0.0 0.0 0.0</rateDrift>
      <rateGaussianNoise>0.0 0.0 0.0</rateGaussianNoise>
      <headingDrift>0.0</headingDrift>
      <headingGaussianNoise>0.00</headingGaussianNoise>
    </plugin>
    <plugin filename="libam_gazebo_wheelencoder.so" name="am_gazebo_wheelencoder">
  </plugin>
    <plugin filename="libhector_gazebo_ros_gps.so" name="automower_gps_sim">
      <alwaysOn>true</alwaysOn>
      <updateRate>4.0</updateRate>
      <bodyName>base_link</bodyName>
      <topicName>fix</topicName>
      <velocityTopicName>fix_vel</velocityTopicName>
      <drift>5.0 5.0 5.0</drift>
      <gaussianNoise>0.1 0.1 0.1</gaussianNoise>
      <velocityDrift>0 0 0</velocityDrift>
      <velocityGaussianNoise>0.1 0.1 0.1</velocityGaussianNoise>
    </plugin>
  </gazebo>
  <gazebo reference="base_link">
    <sensor name="automower_sensor" type="contact">
      <always_on>true</always_on>
      <update_rate>50</update_rate>
      <contact>
        <collision>base_link_collision</collision>
      </contact>
      <plugin filename="libam_gazebo_sensors.so" name="automower_sensors_plugin">
        <always_on>true</always_on>
        <update_rate>20</update_rate>
        <bumperTopicName>sensor_status</bumperTopicName>
        <loopTopicName>loop</loopTopicName>
        <!-- 0x01 = FC, 0x02 = FR, 0x04 = RL, 0x08 = RR -->
        <loopOutsideSensors>15</loopOutsideSensors>
      </plugin>
    </sensor>
  </gazebo>
</robot>
